Workbook

Sheet Pokemon
A1: key | B1: en | C1: ja | D1: fr | E1: de | F1: es | G1: it | H1: ko | I1: zh_HK | J1: zh | K1: es_149
A2: =CONCATENATE("NAME_PkMn_", UPPER(B2)) | B2: Bulbasaur | C2: フシギダネ | D2: Bulbizarre | E2: Bisasam | F2: =B2 | G2: =B2 | H2: 이상해씨 | I2: =IFERROR(__xludf.DUMMYFUNCTION("GOOGLETRANSLATE(J2,""zh_HANS"",""zh_HANT"")"),"妙蛙種子") | J2: 妙蛙种子 | K2: =F2
A3: =CONCATENATE("NAME_PkMn_", UPPER(B3)) | B3: Ivysaur | C3: フシギソウ | D3: Herbizarre | E3: Bisaknosp | F3: =B3 | G3: =B3 | H3: 이상해풀 | I3: =J3 | J3: 妙蛙草 | K3: =F3
A4: =CONCATENATE("NAME_PkMn_", UPPER(B4)) | B4: Venusaur | C4: フシギバナ | D4: Florizarre | E4: Bisaflor | F4: =B4 | G4: =B4 | H4: 이상해꽃 | I4: =J4 | J4: 妙蛙花 | K4: =F4
A5: =CONCATENATE("NAME_PkMn_", UPPER(B5)) | B5: Charmander | C5: ヒトカゲ | D5: Salamèche | E5: Glumanda | F5: =B5 | G5: =B5 | H5: 파이리 | I5: =IFERROR(__xludf.DUMMYFUNCTION("GOOGLETRANSLATE(J5,""zh_HANS"",""zh_HANT"")"),"小火龍") | J5: 小火龙 | K5: =F5
A6: =CONCATENATE("NAME_PkMn_", UPPER(B6)) | B6: Charmeleon | C6: リザード | D6: Reptincel | E6: Glutexo | F6: =B6 | G6: =B6 | H6: 리자드 | I6: =IFERROR(__xludf.DUMMYFUNCTION("GOOGLETRANSLATE(J6,""zh_HANS"",""zh_HANT"")"),"火恐龍") | J6: 火恐龙 | K6: =F6
A7: =CONCATENATE("NAME_PkMn_", UPPER(B7)) | B7: Charizard | C7: リザードン | D7: Dracaufeu | E7: Glurak | F7: =B7 | G7: =B7 | H7: 리자몽 | I7: =IFERROR(__xludf.DUMMYFUNCTION("GOOGLETRANSLATE(J7,""zh_HANS"",""zh_HANT"")"),"噴火龍") | J7: 喷火龙 | K7: =F7
A8: =CONCATENATE("NAME_PkMn_", UPPER(B8)) | B8: Squirtle | C8: ゼニガメ | D8: Carapuce | E8: Schiggy | F8: =B8 | G8: =B8 | H8: 꼬부기 | I8: =IFERROR(__xludf.DUMMYFUNCTION("GOOGLETRANSLATE(J8,""zh_HANS"",""zh_HANT"")"),"傑尼龜") | J8: 杰尼龟 | K8: =F8
A9: =CONCATENATE("NAME_PkMn_", UPPER(B9)) | B9: Wartortle | C9: カメール | D9: Carabaffe | E9: Schillok | F9: =B9 | G9: =B9 | H9: 어니부기 | I9: =IFERROR(__xludf.DUMMYFUNCTION("GOOGLETRANSLATE(J9,""zh_HANS"",""zh_HANT"")"),"卡咪龜") | J9: 卡咪龟 | K9: =F9
A10: =CONCATENATE("NAME_PkMn_", UPPER(B10)) | B10: Blastoise | C10: カメックス | D10: Tortank | E10: Turtok | F10: =B10 | G10: =B10 | H10: 거북왕 | I10: =IFERROR(__xludf.DUMMYFUNCTION("GOOGLETRANSLATE(J10,""zh_HANS"",""zh_HANT"")"),"水箭龜") | J10: 水箭龟 | K10: =F10
A11: =CONCATENATE("NAME_PkMn_", UPPER(B11)) | B11: Caterpie | C11: キャタピー | D11: Chenipan | E11: Raupy | F11: =B11 | G11: =B11 | H11: 캐터피 | I11: =IFERROR(__xludf.DUMMYFUNCTION("GOOGLETRANSLATE(J11,""zh_HANS"",""zh_HANT"")"),"綠毛蟲") | J11: 绿毛虫 | K11: =F11
A12: =CONCATENATE("NAME_PkMn_", UPPER(B12)) | B12: Metapod | C12: トランセル | D12: Chrysacier | E12: Safcon | F12: =B12 | G12: =B12 | H12: 단데기 | I12: 鐵甲蛹 | J12: =IFERROR(__xludf.DUMMYFUNCTION("GOOGLETRANSLATE(I12,""zh_HANT"",""zh_HANS"")"),"铁甲蛹") | K12: =F12
A13: =CONCATENATE("NAME_PkMn_", UPPER(B13)) | B13: Butterfree | C13: バタフリー | D13: Papilusion | E13: Smettbo | F13: =B13 | G13: =B13 | H13: 버터플 | I13: 巴大蝶 | J13: =I13 | K13: =F13
A14: =CONCATENATE("NAME_PkMn_", UPPER(B14)) | B14: Weedle | C14: ビードル | D14: Aspicot | E14: Hornliu | F14: =B14 | G14: =B14 | H14: 뿔충이 | I14: 獨角蟲 | J14: =IFERROR(__xludf.DUMMYFUNCTION("GOOGLETRANSLATE(I14,""zh_HANT"",""zh_HANS"")"),"独角虫") | K14: =F14
A15: =CONCATENATE("NAME_PkMn_", UPPER(B15)) | B15: Kakuna | C15: コクーン | D15: Coconfort | E15: Kokuna | F15: =B15 | G15: =B15 | H15: 딱충이 | I15: 獨角蟲 | J15: =IFERROR(__xludf.DUMMYFUNCTION("GOOGLETRANSLATE(I15,""zh_HANT"",""zh_HANS"")"),"独角虫") | K15: =F15
A16: =CONCATENATE("NAME_PkMn_", UPPER(B16)) | B16: Beedrill | C16: スピアー | D16: Dardargnan | E16: Bibor | F16: =B16 | G16: =B16 | H16: 독침붕 | I16: =J16 | J16: 大针蜂 | K16: =F16
A17: =CONCATENATE("NAME_PkMn_", UPPER(B17)) | B17: Pidgey | C17: ポッポ | D17: Roucool | E17: Taubsi | F17: =B17 | G17: =B17 | H17: 구구 | I17: 波波 | J17: =I17 | K17: =F17
A18: =CONCATENATE("NAME_PkMn_", UPPER(B18)) | B18: Pidgeotto | C18: ピジョン | D18: Roucoups | E18: Tauboga | F18: =B18 | G18: =B18 | H18: 피죤 | I18: 比比鳥 | J18: =IFERROR(__xludf.DUMMYFUNCTION("GOOGLETRANSLATE(I18,""zh_HANT"",""zh_HANS"")"),"比比鸟") | K18: =F18
A19: =CONCATENATE("NAME_PkMn_", UPPER(B19)) | B19: Pidgeot | C19: ピジョット | D19: Roucarnage | E19: Tauboss | F19: =B19 | G19: =B19 | H19: 피죤투 | I19: =IFERROR(__xludf.DUMMYFUNCTION("GOOGLETRANSLATE(J19,""zh_HANS"",""zh_HANT"")"),"大比鳥") | J19: 大比鸟 | K19: =F19
A20: =CONCATENATE("NAME_PkMn_", UPPER(B20)) | B20: Rattata | C20: コラッタ | D20: =B20 | E20: Rattfratz | F20: =B20 | G20: =B20 | H20: 꼬렛 | I20: 小拉達 | J20: =IFERROR(__xludf.DUMMYFUNCTION("GOOGLETRANSLATE(I20,""zh_HANT"",""zh_HANS"")"),"小拉达") | K20: =F20
A21: =CONCATENATE("NAME_PkMn_", UPPER(B21)) | B21: Raticate | C21: ラッタ | D21: Rattatac | E21: Rattikarl | F21: =B21 | G21: =B21 | H21: 레트라 | I21: 拉達 | J21: =IFERROR(__xludf.DUMMYFUNCTION("GOOGLETRANSLATE(I21,""zh_HANT"",""zh_HANS"")"),"拉达") | K21: =F21
A22: =CONCATENATE("NAME_PkMn_", UPPER(B22)) | B22: Spearow | C22: オニスズメ | D22: Piafabec | E22: Habitak | F22: =B22 | G22: =B22 | H22: 깨비참 | I22: 烈雀 | J22: =I22 | K22: =F22
A23: =CONCATENATE("NAME_PkMn_", UPPER(B23)) | B23: Fearow | C23: オニドリル | D23: Rapasdepic | E23: Ibitak | F23: =B23 | G23: =B23 | H23: 깨비드릴조 | I23: 大嘴雀 | J23: =I23 | K23: =F23
A24: =CONCATENATE("NAME_PkMn_", UPPER(B24)) | B24: Ekans | C24: アーボ | D24: Abo | E24: Rettan | F24: =B24 | G24: =B24 | H24: 아보 | I24: 阿柏蛇 | J24: =I24 | K24: =F24
A25: =CONCATENATE("NAME_PkMn_", UPPER(B25)) | B25: Arbok | C25: アーボック | D25: =B25 | E25: =B25 | F25: =B25 | G25: =B25 | H25: 아보크 | I25: 阿柏怪 | J25: =I25 | K25: =F25
A26: =CONCATENATE("NAME_PkMn_", UPPER(B26)) | B26: Pikachu | C26: ピカチュウ | D26: =B26 | E26: =B26 | F26: =B26 | G26: =B26 | H26: 피카츄 | I26: =J26 | J26: 皮卡丘 | K26: =F26
A27: =CONCATENATE("NAME_PkMn_", UPPER(B27)) | B27: Raichu | C27: ライチュウ | D27: =B27 | E27: =B27 | F27: =B27 | G27: =B27 | H27: 라이츄 | I27: 雷丘 | J27: =I27 | K27: =F27
A28: =CONCATENATE("NAME_PkMn_", UPPER(B28)) | B28: Sandshrew | C28: サンド | D28: Sabelette | E28: Sandan | F28: =B28 | G28: =B28 | H28: 모래두지 | I28: 穿山鼠 | J28: =I28 | K28: =F28
A29: =CONCATENATE("NAME_PkMn_", UPPER(B29)) | B29: Sandslash | C29: サンドパン | D29: Sablaireau | E29: Sandamer | F29: =B29 | G29: =B29 | H29: 고지 | I29: 穿山王 | J29: =I29 | K29: =F29
A30: NAME_PkMn_NIDORAN-F | B30: =CONCATENATE("Nidoran", CHAR(9792)) | C30: ニドラン♀ | D30: =B30 | E30: Nidoran-W | F30: =B30 | G30: =B30 | H30: 니드런♀ | I30: 尼多蘭 | J30: =IFERROR(__xludf.DUMMYFUNCTION("GOOGLETRANSLATE(I30,""zh_HANT"",""zh_HANS"")"),"尼多兰") | K30: =F30
A31: =CONCATENATE("NAME_PkMn_", UPPER(B31)) | B31: Nidorina | C31: ニドリーナ | D31: =B31 | E31: =B31 | F31: =B31 | G31: =B31 | H31: 니드리나 | I31: 尼多娜 | J31: =I31 | K31: =F31
A32: =CONCATENATE("NAME_PkMn_", UPPER(B32)) | B32: Nidoqueen | C32: ニドクイン | D32: =B32 | E32: =B32 | F32: =B32 | G32: =B32 | H32: 니드퀸 | I32: 尼多后 | J32: =I32 | K32: =F32
A33: NAME_PkMn_NIDORAN-M | B33: =CONCATENATE("Nidoran", CHAR(9794)) | C33: ニドラン♂ | D33: =B33 | E33: Nidoran-M | F33: =B33 | G33: =B33 | H33: 니드런♂ | I33: 尼多朗 | J33: =I33 | K33: =F33
A34: =CONCATENATE("NAME_PkMn_", UPPER(B34)) | B34: Nidorino | C34: ニドリーノ | D34: =B34 | E34: =B34 | F34: =B34 | G34: =B34 | H34: 니드리노 | I34: 尼多力諾 | J34: =IFERROR(__xludf.DUMMYFUNCTION("GOOGLETRANSLATE(I34,""zh_HANT"",""zh_HANS"")"),"尼多力诺") | K34: =F34
A35: =CONCATENATE("NAME_PkMn_", UPPER(B35)) | B35: Nidoking | C35: ニドキング | D35: =B35 | E35: =B35 | F35: =B35 | G35: =B35 | H35: 니드킹 | I35: 尼多王 | J35: =I35 | K35: =F35
A36: =CONCATENATE("NAME_PkMn_", UPPER(B36)) | B36: Clefairy | C36: ピッピ | D36: Mélofée | E36: Piepi | F36: =B36 | G36: =B36 | H36: 삐삐 | I36: 皮皮 | J36: =I36 | K36: =F36
A37: =CONCATENATE("NAME_PkMn_", UPPER(B37)) | B37: Clefable | C37: ピクシー | D37: Mélodelfe | E37: Pixi | F37: =B37 | G37: =B37 | H37: 픽시 | I37: 皮可西 | J37: =I37 | K37: =F37
A38: =CONCATENATE("NAME_PkMn_", UPPER(B38)) | B38: Vulpix | C38: ロコン | D38: Goupix | E38: =B38 | F38: =B38 | G38: =B38 | H38: 식스테일 | I38: 六尾 | J38: =I38 | K38: =F38
A39: =CONCATENATE("NAME_PkMn_", UPPER(B39)) | B39: Ninetales | C39: キュウコン | D39: Feunard | E39: Vulnona | F39: =B39 | G39: =B39 | H39: 나인테일 | I39: 九尾 | J39: =I39 | K39: =F39
A40: =CONCATENATE("NAME_PkMn_", UPPER(B40)) | B40: Jigglypuff | C40: プリン | D40: Rondoudou | E40: Pummeluff | F40: =B40 | G40: =B40 | H40: 푸린 | I40: 胖丁 | J40: =I40 | K40: =F40
...

Sheet Forms
A1: =Pokemon!A1 | B1: =Pokemon!B1 | C1: =Pokemon!C1 | D1: =Pokemon!D1 | E1: =Pokemon!E1 | F1: =Pokemon!F1 | G1: =Pokemon!G1 | H1: =Pokemon!H1 | ... K1: =Pokemon!K1
A2: =CONCATENATE("NAME_FORM_", SUBSTITUTE(UPPER(B2), " ", "")) | B2: Male | C2: オス | D2: Mâle | E2: Männlich | F2: Macho | G2: Maschio | H2: 수컷 | I2: 雄性 | J2: =I2 | K2: =F2
A3: =CONCATENATE("NAME_FORM_", SUBSTITUTE(UPPER(B3), " ", "")) | B3: Female | C3: メス | D3: Femelle | E3: Weiblich | F3: Hembra | G3: Femmina | H3: 암컷 | I3: 雌性 | J3: =I3 | K3: =F3
A4: =CONCATENATE("NAME_FORM_", SUBSTITUTE(UPPER(B4), " ", "")) | B4: Shiny | C4: ひかる | D4: Chromatique | E4: Schillerndes | F4: Variocolor | G4: Cromatico | H4: 빛나는 | I4: 發光 | J4: =IFERROR(__xludf.DUMMYFUNCTION("GOOGLETRANSLATE(I4,""zh_HANT"",""zh_HANS"")"),"发光") | K4: =F4
A5: =CONCATENATE("NAME_FORM_", SUBSTITUTE(UPPER(B5), " ", "")) | B5: Normal Form | C5: ポワルンのすがた | D5: Forme Normale | E5: Normalform | F5: =CONCATENATE("Forma ",Types!F2) | G5: Forma Castform | H5: 캐스퐁의 모습 | I5: 飄浮泡泡的樣子 | J5: =IFERROR(__xludf.DUMMYFUNCTION("GOOGLETRANSLATE(I5,""zh_HANT"",""zh_HANS"")"),"飘浮泡泡的样子") | K5: =F5
A6: =CONCATENATE("NAME_FORM_", SUBSTITUTE(UPPER(B6), " ", "")) | B6: Sunny Form | C6: たいようのすがた | D6: Forme Solaire | E6: Sonnenform | F6: Forma Sol | G6: Forma Sole | H6: 태양의 모습 | I6: 太陽的樣子 | J6: =IFERROR(__xludf.DUMMYFUNCTION("GOOGLETRANSLATE(I6,""zh_HANT"",""zh_HANS"")"),"太阳的样子") | K6: =F6
A7: =CONCATENATE("NAME_FORM_", SUBSTITUTE(UPPER(B7), " ", "")) | B7: Rainy Form | C7: あまみずのすがた | D7: Forme Eau de Pluie | E7: Regenform | F7: Forma Lluvia | G7: Forma Pioggia | H7: 빗방울의 모습 | I7: 雨水的樣子 | J7: =IFERROR(__xludf.DUMMYFUNCTION("GOOGLETRANSLATE(I7,""zh_HANT"",""zh_HANS"")"),"雨水的样子") | K7: =F7
A8: =CONCATENATE("NAME_FORM_", SUBSTITUTE(UPPER(B8), " ", "")) | B8: Snowy Form | C8: ゆきぐものすがた | D8: Forme Blizzard | E8: Schneeform | F8: Forma Nieve | G8: Forma Nuvola di Neve | H8: 설운의 모습 | I8: 雪雲的樣子 | J8: =IFERROR(__xludf.DUMMYFUNCTION("GOOGLETRANSLATE(I8,""zh_HANT"",""zh_HANS"")"),"雪云的样子") | K8: =F8
A9: =CONCATENATE("NAME_FORM_", SUBSTITUTE(UPPER(B9), " ", "")) | B9: =CONCATENATE(B5, "e") | C9: ノーマルフォルム | D9: =D5 | E9: =E5 | F9: =F5 | G9: Forma Normale | H9: 노말폼 | I9: 普通形態 | J9: =IFERROR(__xludf.DUMMYFUNCTION("GOOGLETRANSLATE(I9,""zh_HANT"",""zh_HANS"")"),"普通形态") | K9: =F9
A10: =CONCATENATE("NAME_FORM_", SUBSTITUTE(UPPER(B10), " ", "")) | B10: Attack Forme | C10: アタックフォルム | D10: Forme Attaque | E10: Angriffsform | F10: Forma Ataque | G10: Forma Attacco | H10: 어택폼 | I10: 攻擊形態 | J10: =IFERROR(__xludf.DUMMYFUNCTION("GOOGLETRANSLATE(I10,""zh_HANT"",""zh_HANS"")"),"攻击形态") | K10: =F10
A11: =CONCATENATE("NAME_FORM_", SUBSTITUTE(UPPER(B11), " ", "")) | B11: Defence Forme | C11: ヂィフェンスフォルム | D11: Forme Défense | E11: Verteidigungsform | F11: Forma Defensa | G11: Forma Difesa | H11: 디펜스폼 | I11: 防禦形態 | J11: =IFERROR(__xludf.DUMMYFUNCTION("GOOGLETRANSLATE(I11,""zh_HANT"",""zh_HANS"")"),"防御形态") | K11: =F11
A12: =CONCATENATE("NAME_FORM_", SUBSTITUTE(UPPER(B12), " ", "")) | B12: Speed Forme | C12: スピードフォルム | D12: Forme Vitesse | E12: Initiativeform | F12: Forma Velocidad | G12: Forma Velocità | H12: 스피드폼 | I12: 速度形態 | J12: =IFERROR(__xludf.DUMMYFUNCTION("GOOGLETRANSLATE(I12,""zh_HANT"",""zh_HANS"")"),"速度形态") | K12: =F12
A13: =CONCATENATE("NAME_FORM_", SUBSTITUTE(UPPER(B13), " ", "")) | B13: Plant Cloak | C13: くさきのミノ | D13: Cape Plante | E13: Pflanzenumhang | F13: Tronco Planta | G13: Manto Pianta | H13: 초목도롱 | I13: 草木蓑衣 | J13: =I13 | K13: =F13
A14: =CONCATENATE("NAME_FORM_", SUBSTITUTE(UPPER(B14), " ", "")) | B14: Sandy Cloak | C14: すなちのミノ | D14: Cape Sable | E14: Sandumhang | F14: Tronco Arena | G14: Manto Sabbia | H14: 모래땅도롱 | I14: 砂土蓑衣 | J14: =I14 | K14: =F14
A15: =CONCATENATE("NAME_FORM_", SUBSTITUTE(UPPER(B15), " ", "")) | B15: Trash Cloak | C15: ゴミのミノ | D15: Cape Déchet | E15: Lumpenumhang | F15: Tronco Basura | G15: Manto Scarti | H15: 슈레도롱 | I15: 垃圾蓑衣 | J15: =I15 | K15: =F15
A16: =CONCATENATE("NAME_FORM_", SUBSTITUTE(UPPER(B16), " ", "")) | B16: Overcast Form | C16: ネガフォルム | D16: Temps Couvert | E16: Wolkenform | F16: Forma Encapotado | G16: Forma Nuvola | H16: 네거폼 | I16: 陰天形態 | J16: =IFERROR(__xludf.DUMMYFUNCTION("GOOGLETRANSLATE(I16,""zh_HANT"",""zh_HANS"")"),"阴天形态") | K16: =F16
A17: =CONCATENATE("NAME_FORM_", SUBSTITUTE(UPPER(B17), " ", "")) | B17: Sunshine Form | C17: ポシフォルム | D17: Temps Ensoleillé | E17: =E6 | F17: Forma Soleado | G17: Forma Splendore | H17: 포지폼 | I17: 晴天形態 | J17: =IFERROR(__xludf.DUMMYFUNCTION("GOOGLETRANSLATE(I17,""zh_HANT"",""zh_HANS"")"),"晴天形态") | K17: =F17
A18: =CONCATENATE("NAME_FORM_", SUBSTITUTE(UPPER(B18), " ", "")) | B18: West Sea | C18: にしのうみ | D18: Mer Occident | E18: Westliches Meer | F18: Mar Oest | G18: Mare Ovest | H18: 서쪽바다 | I18: 西海 | J18: =I18 | K18: =F18
A19: =CONCATENATE("NAME_FORM_", SUBSTITUTE(UPPER(B19), " ", "")) | B19: East Sea | C19: ひがしのうみ | D19: Mer Orient | E19: Östliches Meer | F19: Mar Est | G19: Mare Est | H19: 동쪽바다 | I19: 東海 | J19: =I19 | K19: =F19
A20: =CONCATENATE("NAME_FORM_", SUBSTITUTE(UPPER(B20), " ", "")) | B20: Heat Rotom | C20: =CONCATENATE("ヒート", Pokemon!C480) | D20: Motisma Chaleur | E20: Hitze-Rotom | F20: Rotom Claor | G20: =CONCATENATE(F20, "e") | H20: 히트로토무 | I20: 加熱洛托姆 | J20: =IFERROR(__xludf.DUMMYFUNCTION("GOOGLETRANSLATE(I20,""zh_HANT"",""zh_HANS"")"),"加热洛托姆") | K20: =F20
A21: =CONCATENATE("NAME_FORM_", SUBSTITUTE(UPPER(B21), " ", "")) | B21: Wash Rotom | C21: =CONCATENATE("ウォッシュ", Pokemon!C480) | D21: Motisma Lavage | E21: Wasch-Rotom | F21: Rotom Lavado | G21: Rotom Lavaggio | H21: 워시로토무 | I21: 清洗洛托姆 | J21: =I21 | K21: =F21
A22: =CONCATENATE("NAME_FORM_", SUBSTITUTE(UPPER(B22), " ", "")) | B22: Frost Rotom | C22: =CONCATENATE("フロスト", Pokemon!C480) | D22: Motisma Froid | E22: Frost-Rotom | F22: Rotom Frio | G22: Rotom Gelo | H22: 프로스트로토무 | I22: 結冰洛托姆 | J22: =IFERROR(__xludf.DUMMYFUNCTION("GOOGLETRANSLATE(I22,""zh_HANT"",""zh_HANS"")"),"结冰洛托姆") | K22: =F22
A23: =CONCATENATE("NAME_FORM_", SUBSTITUTE(UPPER(B23), " ", "")) | B23: Fan Rotom | C23: =CONCATENATE("スピン", Pokemon!C480) | D23: Motisma Hélice | E23: Wirbel-Rotom | F23: Rotom Ventilador | G23: Rotom Vortice | H23: 스핀로토무 | I23: 旋轉洛托姆 | J23: =IFERROR(__xludf.DUMMYFUNCTION("GOOGLETRANSLATE(I23,""zh_HANT"",""zh_HANS"")"),"旋转洛托姆") | K23: =F23
A24: =CONCATENATE("NAME_FORM_", SUBSTITUTE(UPPER(B24), " ", "")) | B24: Mow Rotom | C24: =CONCATENATE("カット", Pokemon!C480) | D24: Motisma Tonte | E24: Schneid-Rotom | F24: Rotom Corte | G24: Rotom Taglio | H24: 커트로토무 | I24: 切割洛托姆 | J24: =I24 | K24: =F24
A25: =CONCATENATE("NAME_FORM_", SUBSTITUTE(UPPER(B25), " ", "")) | B25: Altered Forme | C25: アナザーフォルム | D25: Forme Alternative | E25: Wandelform | F25: Forma Modificada | G25: Forma Alterata | H25: 어나더폼 | I25: 別種形態 | J25: =IFERROR(__xludf.DUMMYFUNCTION("GOOGLETRANSLATE(I25,""zh_HANT"",""zh_HANS"")"),"别种形态") | K25: =F25
A26: =CONCATENATE("NAME_FORM_", SUBSTITUTE(UPPER(B26), " ", "")) | B26: Origin Forme | C26: オリジンフォルム | D26: Forme Originelle | E26: Urform | F26: Forma Origen | G26: Forma Origine | H26: 오리진폼 | I26: 起源形態 | J26: =IFERROR(__xludf.DUMMYFUNCTION("GOOGLETRANSLATE(I26,""zh_HANT"",""zh_HANS"")"),"起源形态") | K26: =F26
A27: =CONCATENATE("NAME_FORM_", SUBSTITUTE(UPPER(B27), " ", "")) | B27: Land Forme | C27: ランドフォルム | D27: Forme Terrestre | E27: Landform | F27: Forma Tierra | G27: Forma Terra | H27: 랜드폼 | I27: 陸上形態 | J27: =IFERROR(__xludf.DUMMYFUNCTION("GOOGLETRANSLATE(I27,""zh_HANT"",""zh_HANS"")"),"陆上形态") | K27: =F27
A28: =CONCATENATE("NAME_FORM_", SUBSTITUTE(UPPER(B28), " ", "")) | B28: Sky Forme | C28: スカイフォルム | D28: Forme Céleste | E28: Zenitform | F28: =G28 | G28: Forma Cielo | H28: 스카이폼 | I28: 天空形態 | J28: =IFERROR(__xludf.DUMMYFUNCTION("GOOGLETRANSLATE(I28,""zh_HANT"",""zh_HANS"")"),"天空形态") | K28: =F28
A29: NAME_FORM_NORMALTYPE | B29: =CONCATENATE(Types!B2,"-type") | C29: =CONCATENATE(Types!C2,"タイプ") | D29: Type Normal | E29: =CONCATENATE("Typen ",Types!E2) | F29: =CONCATENATE("Tipo ",Types!F2) | G29: =CONCATENATE("Tipo ",Types!G2) | H29: =CONCATENATE(Types!H2,"타입") | I29: =IFERROR(__xludf.DUMMYFUNCTION("GOOGLETRANSLATE(J29,""zh_HANS"",""zh_HANT"")"),"一般屬性") | J29: =CONCATENATE(Types!J2,"属性") | K29: =F29
A30: NAME_FORM_FIGHTINGTYPE | B30: =CONCATENATE(Types!B3,"-type") | C30: =CONCATENATE(Types!C3,"タイプ") | D30: Type Combat | E30: =CONCATENATE("Typen ",Types!E3) | F30: =CONCATENATE("Tipo ",Types!F3) | G30: =CONCATENATE("Tipo ",Types!G3) | H30: =CONCATENATE(Types!H3,"타입") | I30: =IFERROR(__xludf.DUMMYFUNCTION("GOOGLETRANSLATE(J30,""zh_HANS"",""zh_HANT"")"),"格鬥屬性") | J30: =CONCATENATE(Types!J3,"属性") | K30: =F30
A31: NAME_FORM_FLYINGTYPE | B31: =CONCATENATE(Types!B4,"-type") | C31: =CONCATENATE(Types!C4,"タイプ") | D31: Type Vol | E31: =CONCATENATE("Typen ",Types!E4) | F31: =CONCATENATE("Tipo ",Types!F4) | G31: =CONCATENATE("Tipo ",Types!G4) | H31: =CONCATENATE(Types!H4,"타입") | I31: =IFERROR(__xludf.DUMMYFUNCTION("GOOGLETRANSLATE(J31,""zh_HANS"",""zh_HANT"")"),"飛行屬性") | J31: =CONCATENATE(Types!J4,"属性") | K31: =F31
A32: NAME_FORM_POISONTYPE | B32: =CONCATENATE(Types!B5,"-type") | C32: =CONCATENATE(Types!C5,"タイプ") | D32: Type Poison | E32: =CONCATENATE("Typen ",Types!E5) | F32: =CONCATENATE("Tipo ",Types!F5) | G32: =CONCATENATE("Tipo ",Types!G5) | H32: =CONCATENATE(Types!H5,"타입") | I32: =IFERROR(__xludf.DUMMYFUNCTION("GOOGLETRANSLATE(J32,""zh_HANS"",""zh_HANT"")"),"毒屬性") | J32: =CONCATENATE(Types!J5,"属性") | K32: =F32
A33: NAME_FORM_GROUNDTYPE | B33: =CONCATENATE(Types!B6,"-type") | C33: =CONCATENATE(Types!C6,"タイプ") | D33: Type Sol | E33: =CONCATENATE("Typen ",Types!E6) | F33: =CONCATENATE("Tipo ",Types!F6) | G33: =CONCATENATE("Tipo ",Types!G6) | H33: =CONCATENATE(Types!H6,"타입") | I33: =IFERROR(__xludf.DUMMYFUNCTION("GOOGLETRANSLATE(J33,""zh_HANS"",""zh_HANT"")"),"地面屬性") | J33: =CONCATENATE(Types!J6,"属性") | K33: =F33
A34: NAME_FORM_ROCKTYPE | B34: =CONCATENATE(Types!B7,"-type") | C34: =CONCATENATE(Types!C7,"タイプ") | D34: Type Roche | E34: =CONCATENATE("Typen ",Types!E7) | F34: =CONCATENATE("Tipo ",Types!F7) | G34: =CONCATENATE("Tipo ",Types!G7) | H34: =CONCATENATE(Types!H7,"타입") | I34: =IFERROR(__xludf.DUMMYFUNCTION("GOOGLETRANSLATE(J34,""zh_HANS"",""zh_HANT"")"),"岩石屬性") | J34: =CONCATENATE(Types!J7,"属性") | K34: =F34
A35: NAME_FORM_BUGTYPE | B35: =CONCATENATE(Types!B8,"-type") | C35: =CONCATENATE(Types!C8,"タイプ") | D35: Type Insecte | E35: =CONCATENATE("Typen ",Types!E8) | F35: =CONCATENATE("Tipo ",Types!F8) | G35: =CONCATENATE("Tipo ",Types!G8) | H35: =CONCATENATE(Types!H8,"타입") | I35: =IFERROR(__xludf.DUMMYFUNCTION("GOOGLETRANSLATE(J35,""zh_HANS"",""zh_HANT"")"),"蟲屬性") | J35: =CONCATENATE(Types!J8,"属性") | K35: =F35
A36: NAME_FORM_GHOSTTYPE | B36: =CONCATENATE(Types!B9,"-type") | C36: =CONCATENATE(Types!C9,"タイプ") | D36: Type Spectre | E36: =CONCATENATE("Typen ",Types!E9) | F36: =CONCATENATE("Tipo ",Types!F9) | G36: =CONCATENATE("Tipo ",Types!G9) | H36: =CONCATENATE(Types!H9,"타입") | I36: =IFERROR(__xludf.DUMMYFUNCTION("GOOGLETRANSLATE(J36,""zh_HANS"",""zh_HANT"")"),"幽靈屬性") | J36: =CONCATENATE(Types!J9,"属性") | K36: =F36
A37: NAME_FORM_STEELTYPE | B37: =CONCATENATE(Types!B10,"-type") | C37: =CONCATENATE(Types!C10,"タイプ") | D37: Type Acier | E37: =CONCATENATE("Typen ",Types!E10) | F37: =CONCATENATE("Tipo ",Types!F10) | G37: =CONCATENATE("Tipo ",Types!G10) | H37: =CONCATENATE(Types!H10,"타입") | I37: =IFERROR(__xludf.DUMMYFUNCTION("GOOGLETRANSLATE(J37,""zh_HANS"",""zh_HANT"")"),"鋼屬性") | J37: =CONCATENATE(Types!J10,"属性") | K37: =F37
A38: NAME_FORM_FIRETYPE | B38: =CONCATENATE(Types!B11,"-type") | C38: =CONCATENATE(Types!C11,"タイプ") | D38: Type Feu | E38: =CONCATENATE("Typen ",Types!E11) | F38: =CONCATENATE("Tipo ",Types!F11) | G38: =CONCATENATE("Tipo ",Types!G11) | H38: =CONCATENATE(Types!H11,"타입") | I38: =IFERROR(__xludf.DUMMYFUNCTION("GOOGLETRANSLATE(J38,""zh_HANS"",""zh_HANT"")"),"火屬性") | J38: =CONCATENATE(Types!J11,"属性") | K38: =F38
A39: NAME_FORM_WATERTYPE | B39: =CONCATENATE(Types!B12,"-type") | C39: =CONCATENATE(Types!C12,"タイプ") | D39: Type Eau | E39: =CONCATENATE("Typen ",Types!E12) | F39: =CONCATENATE("Tipo ",Types!F12) | G39: =CONCATENATE("Tipo ",Types!G12) | H39: =CONCATENATE(Types!H12,"타입") | I39: =IFERROR(__xludf.DUMMYFUNCTION("GOOGLETRANSLATE(J39,""zh_HANS"",""zh_HANT"")"),"水屬性") | J39: =CONCATENATE(Types!J12,"属性") | K39: =F39
A40: NAME_FORM_GRASSTYPE | B40: =CONCATENATE(Types!B13,"-type") | C40: =CONCATENATE(Types!C13,"タイプ") | D40: Type Plante | E40: =CONCATENATE("Typen ",Types!E13) | F40: =CONCATENATE("Tipo ",Types!F13) | G40: =CONCATENATE("Tipo ",Types!G13) | H40: =CONCATENATE(Types!H13,"타입") | I40: =IFERROR(__xludf.DUMMYFUNCTION("GOOGLETRANSLATE(J40,""zh_HANS"",""zh_HANT"")"),"草屬性") | J40: =CONCATENATE(Types!J13,"属性") | K40: =F40
...

Sheet Categories
A1: =Pokemon!A1 | B1: =Pokemon!B1 | C1: =Pokemon!C1 | D1: =Pokemon!D1 | E1: =Pokemon!E1 | F1: =Pokemon!F1 | G1: =Pokemon!G1 | H1: =Pokemon!H1 | ... K1: =Pokemon!K1
A2: =CONCATENATE("CATEGORY_",UPPER(Pokemon!B2)) | B2: Seed | C2: たね | D2: Graine | E2: Samen | F2: Semilla | G2: Seme | H2: 씨앗 | I2: 種子 | J2: =IFERROR(__xludf.DUMMYFUNCTION("GOOGLETRANSLATE(I2, ""zh_HANT"",""zh_HANS"")"),"种子") | K2: =F2
A3: =CONCATENATE("CATEGORY_",UPPER(Pokemon!B3)) | B3: =B2 | C3: =C2 | D3: =D2 | E3: =E2 | F3: =F2 | G3: =G2 | H3: =H2 | I3: =I2 | J3: =J2 | K3: =F3
A4: =CONCATENATE("CATEGORY_",UPPER(Pokemon!B4)) | B4: =B2 | C4: =C2 | D4: =D2 | E4: =E2 | F4: =F2 | G4: =G2 | H4: =H2 | I4: =I2 | J4: =J2 | K4: =F4
A5: =CONCATENATE("CATEGORY_",UPPER(Pokemon!B5)) | B5: Lizard | C5: とかげ | D5: Lézard | E5: Echse | F5: Lagartija | G5: Lucertola | H5: 도롱뇽 | I5: 蜥蜴 | J5: =I5 | K5: =F5
A6: =CONCATENATE("CATEGORY_",UPPER(Pokemon!B6)) | B6: Flame | C6: かえん | D6: Flamme | E6: =D6 | F6: Llama | G6: Fiamma | H6: 화염 | I6: 火焰 | J6: =I6 | K6: =F6
A7: =CONCATENATE("CATEGORY_",UPPER(Pokemon!B7)) | B7: =B6 | C7: =C6 | D7: =D6 | E7: =E6 | F7: =F6 | G7: =G6 | H7: =H6 | I7: =I6 | J7: =J6 | K7: =F7
A8: =CONCATENATE("CATEGORY_",UPPER(Pokemon!B8)) | B8: Tiny Turtle | C8: かめのこ | D8: Minitortue | E8: Minikröte | F8: Tortuguita | G8: Tartaghina | H8: 꼬마거북 | I8: 小龜 | J8: =IFERROR(__xludf.DUMMYFUNCTION("GOOGLETRANSLATE(I8, ""zh_HANT"",""zh_HANS"")"),"小龟") | K8: =F8
A9: =CONCATENATE("CATEGORY_",UPPER(Pokemon!B9)) | B9: Turtle | C9: かめ | D9: Tortue | E9: Kröte | F9: Tortuga | G9: Tartaruga | H9: 거북 | I9: =IFERROR(__xludf.DUMMYFUNCTION("GOOGLETRANSLATE(J9,""zh_HANS"",""zh_HANT"")"),"龜") | J9: 龟 | K9: =F9
A10: =CONCATENATE("CATEGORY_",UPPER(Pokemon!B10)) | B10: Shellfish | C10: こうら | D10: Carapace | E10: Schaltier | F10: Marisco | G10: Crostaceo | H10: 껍질 | I10: 甲殼 | J10: =IFERROR(__xludf.DUMMYFUNCTION("GOOGLETRANSLATE(I10, ""zh_HANT"",""zh_HANS"")"),"甲壳") | K10: =F10
A11: =CONCATENATE("CATEGORY_",UPPER(Pokemon!B11)) | B11: Worm | C11: いもむし | D11: Ver | E11: Wurm | F11: Gusano | G11: Baco | H11: 애벌레 | I11: 蟲寶寶 | J11: =IFERROR(__xludf.DUMMYFUNCTION("GOOGLETRANSLATE(I11, ""zh_HANT"",""zh_HANS"")"),"虫宝宝") | K11: =F11
A12: =CONCATENATE("CATEGORY_",UPPER(Pokemon!B12)) | B12: Cocoon | C12: さなぎ | D12: Cocon | E12: Kokon | F12: Capullo | G12: Bozzolo | H12: 번데기 | I12: 蛹 | J12: =I12 | K12: =F12
A13: =CONCATENATE("CATEGORY_",UPPER(Pokemon!B13)) | B13: Butterfly | C13: ちょうちょ | D13: Papillon | E13: Falter | F13: Mariposa | G13: Farfalla | H13: 나비 | I13: 蝴蝶 | J13: =I13 | K13: =F13
A14: =CONCATENATE("CATEGORY_",UPPER(Pokemon!B14)) | B14: Hairy Bug | C14: えむし | D14: Insectopic | E14: Raupe | F14: Oruga | G14: Millepiedi | H14: 송충이 | I14: 毛毛蟲 | J14: =IFERROR(__xludf.DUMMYFUNCTION("GOOGLETRANSLATE(I14, ""zh_HANT"",""zh_HANS"")"),"毛毛虫") | K14: =F14
A15: =CONCATENATE("CATEGORY_",UPPER(Pokemon!B15)) | B15: =B12 | C15: =C12 | D15: =D12 | E15: =E12 | F15: =F12 | G15: =G12 | H15: =H12 | I15: =I12 | J15: =J12 | K15: =F15
A16: =CONCATENATE("CATEGORY_",UPPER(Pokemon!B16)) | B16: Poison Bee | C16: どくばち | D16: Guêpoison | E16: Giftbiene | F16: Abeja Ven. | G16: Velenape | H16: 독벌 | I16: 毒蜂 | J16: =I16 | K16: =F16
A17: =CONCATENATE("CATEGORY_",UPPER(Pokemon!B17)) | B17: Tiny Bird | C17: ことり | D17: Minoiseau | E17: Kleinvogel | F17: Pajarito | G17: Uccellino | H17: 아기새 | I17: 小鳥 | J17: =IFERROR(__xludf.DUMMYFUNCTION("GOOGLETRANSLATE(I17, ""zh_HANT"",""zh_HANS"")"),"小鸟") | K17: =F17
A18: =CONCATENATE("CATEGORY_",UPPER(Pokemon!B18)) | B18: Bird | C18: とり | D18: Oiseau | E18: Vogel | F18: Pájaro | G18: Uccello | H18: 새 | I18: 鳥 | J18: =IFERROR(__xludf.DUMMYFUNCTION("GOOGLETRANSLATE(I18, ""zh_HANT"",""zh_HANS"")"),"鸟") | K18: =F18
A19: =CONCATENATE("CATEGORY_",UPPER(Pokemon!B19)) | B19: =B18 | C19: =C18 | D19: =D18 | E19: =E18 | F19: =F18 | G19: =G18 | H19: =H18 | I19: =I18 | J19: =IFERROR(__xludf.DUMMYFUNCTION("GOOGLETRANSLATE(I19, ""zh_HANT"",""zh_HANS"")"),"鸟") | K19: =F19
A20: =CONCATENATE("CATEGORY_",UPPER(Pokemon!B20)) | B20: Mouse | C20: ねずみ | D20: Souris | E20: Maus | F20: Ratón | G20: Topo | H20: 쥐 | I20: 鼠 | J20: =I20 | K20: =F20
A21: =CONCATENATE("CATEGORY_",UPPER(Pokemon!B21)) | B21: =B20 | C21: =C20 | D21: =D20 | E21: =E20 | F21: =F20 | G21: =G20 | H21: =H20 | I21: =I20 | J21: =J20 | K21: =F21
A22: =CONCATENATE("CATEGORY_",UPPER(Pokemon!B22)) | B22: =B17 | C22: =C17 | D22: =D17 | E22: =E17 | F22: =F17 | G22: =G17 | H22: =H17 | I22: =I17 | J22: =J17 | K22: =F22
A23: =CONCATENATE("CATEGORY_",UPPER(Pokemon!B23)) | B23: Beak | C23: くちばし | D23: Bec-Oiseau | E23: Pickvogel | F23: Pico | G23: Becco | H23: 부리 | I23: 鳥嘴 | J23: =IFERROR(__xludf.DUMMYFUNCTION("GOOGLETRANSLATE(I23, ""zh_HANT"",""zh_HANS"")"),"鸟嘴") | K23: =F23
A24: =CONCATENATE("CATEGORY_",UPPER(Pokemon!B24)) | B24: Snake | C24: へび | D24: Serpent | E24: Schlange | F24: Serpiente | G24: Serpente | H24: 뱀 | I24: 蛇 | J24: =I24 | K24: =F24
A25: =CONCATENATE("CATEGORY_",UPPER(Pokemon!B25)) | B25: Cobra | C25: コブラ | D25: Cobra | E25: Kobra | F25: =B25 | G25: =B25 | H25: 코브라 | I25: 眼鏡蛇 | J25: =IFERROR(__xludf.DUMMYFUNCTION("GOOGLETRANSLATE(I25, ""zh_HANT"",""zh_HANS"")"),"眼镜蛇") | K25: =F25
A26: =CONCATENATE("CATEGORY_",UPPER(Pokemon!B26)) | B26: =B20 | C26: =C20 | D26: =D20 | E26: =E20 | F26: =F20 | G26: =G20 | H26: =H20 | I26: =I20 | J26: =J20 | K26: =F26
A27: =CONCATENATE("CATEGORY_",UPPER(Pokemon!B27)) | B27: =B20 | C27: =C20 | D27: =D20 | E27: =E20 | F27: =F20 | G27: =G20 | H27: =H20 | I27: =I20 | J27: =J20 | K27: =F27
A28: =CONCATENATE("CATEGORY_",UPPER(Pokemon!B28)) | B28: =B20 | C28: =C20 | D28: =D20 | E28: =E20 | F28: =F20 | G28: =G20 | H28: =H20 | I28: =I20 | J28: =J20 | K28: =F28
A29: =CONCATENATE("CATEGORY_",UPPER(Pokemon!B29)) | B29: =B20 | C29: =C20 | D29: =D20 | E29: =E20 | F29: =F20 | G29: =G20 | H29: =H20 | I29: =I20 | J29: =J20 | K29: =F29
A30: CATEGORY_NIDORAN-F | B30: Poison Pin | C30: どくばり | D30: Vénépic | E30: Giftdorn | F30: Pin Veneno | G30: Velenago | H30: 독침 | I30: 毒針 | J30: =IFERROR(__xludf.DUMMYFUNCTION("GOOGLETRANSLATE(I30, ""zh_HANT"",""zh_HANS"")"),"毒针") | K30: =F30
A31: =CONCATENATE("CATEGORY_",UPPER(Pokemon!B31)) | B31: =B30 | C31: =C30 | D31: =D30 | E31: =E30 | F31: =F30 | G31: =G30 | H31: =H30 | I31: =I30 | J31: =J30 | K31: =F31
A32: =CONCATENATE("CATEGORY_",UPPER(Pokemon!B32)) | B32: Drill | C32: ドリル | D32: Perceur | E32: Bohrer | F32: Taladro | G32: Trapano | H32: 드릴 | I32: 鑽錐 | J32: =IFERROR(__xludf.DUMMYFUNCTION("GOOGLETRANSLATE(I32, ""zh_HANT"",""zh_HANS"")"),"钻锥") | K32: =F32
A33: CATEGORY_NIDORAN-M | B33: =B30 | C33: =C30 | D33: =D30 | E33: =E30 | F33: =F30 | G33: =G30 | H33: =H30 | I33: =I30 | J33: =J30 | K33: =F33
A34: =CONCATENATE("CATEGORY_",UPPER(Pokemon!B34)) | B34: =B30 | C34: =C30 | D34: =D30 | E34: =E30 | F34: =F30 | G34: =G30 | H34: =H30 | I34: =I30 | J34: =J30 | K34: =F34
A35: =CONCATENATE("CATEGORY_",UPPER(Pokemon!B35)) | B35: =B32 | C35: =C32 | D35: =D32 | E35: =E32 | F35: =F32 | G35: =G32 | H35: =H32 | I35: =I32 | J35: =J32 | K35: =F35
A36: =CONCATENATE("CATEGORY_",UPPER(Pokemon!B36)) | B36: =Types!B19 | C36: ようせい | D36: =Types!D19 | E36: =Types!E19 | F36: =Types!F19 | G36: Fata | H36: 요정 | I36: =Types!I19 | J36: =Types!J19 | K36: =F36
A37: =CONCATENATE("CATEGORY_",UPPER(Pokemon!B37)) | B37: =B36 | C37: =C36 | D37: =D36 | E37: =E36 | F37: =F36 | G37: =G36 | H37: =H36 | I37: =I36 | J37: =J36 | K37: =F37
A38: =CONCATENATE("CATEGORY_",UPPER(Pokemon!B38)) | B38: Fox | C38: きつね | D38: Renard | E38: Fuchs | F38: Zorro | G38: Volpe | H38: 여우 | I38: 狐狸 | J38: =I38 | K38: =F38
A39: =CONCATENATE("CATEGORY_",UPPER(Pokemon!B39)) | B39: =B38 | C39: =C38 | D39: =D38 | E39: =E38 | F39: =F38 | G39: =G38 | H39: =H38 | I39: =I38 | J39: =J38 | K39: =F39
A40: =CONCATENATE("CATEGORY_",UPPER(Pokemon!B40)) | B40: Balloon | C40: ふうせん | D40: Bouboule | E40: Ballon | F40: Globo | G40: Pallone | H40: 풍선 | I40: 氣球 | J40: =IFERROR(__xludf.DUMMYFUNCTION("GOOGLETRANSLATE(I40, ""zh_HANT"",""zh_HANS"")"),"气球") | K40: =F40
...

Sheet Types
A1: =Pokemon!A1 | B1: =Pokemon!B1 | C1: =Pokemon!C1 | D1: =Pokemon!D1 | E1: =Pokemon!E1 | F1: =Pokemon!F1 | G1: =Pokemon!G1 | H1: =Pokemon!H1 | ... K1: =Pokemon!K1
A2: =CONCATENATE("NAME_TYPE_", UPPER(B2)) | B2: Normal | C2: ノーマル | D2: =B2 | E2: =B2 | F2: =B2 | G2: Normale | H2: 노말 | I2: =J2 | J2: 一般 | K2: =F2
A3: =CONCATENATE("NAME_TYPE_", UPPER(B3)) | B3: Fighting | C3: かくとう | D3: Combat | E3: Kampf | F3: Lucha | G3: Lotta | H3: 격투 | I3: =IFERROR(__xludf.DUMMYFUNCTION("GOOGLETRANSLATE(J3,""zh_HANS"",""zh_HANT"")"),"格鬥") | J3: 格斗 | K3: =F3
A4: =CONCATENATE("NAME_TYPE_", UPPER(B4)) | B4: Flying | C4: ひこう | D4: Vol | E4: Flug | F4: Volador | G4: Volante | H4: 비행 | I4: =IFERROR(__xludf.DUMMYFUNCTION("GOOGLETRANSLATE(J4,""zh_HANS"",""zh_HANT"")"),"飛行") | J4: 飞行 | K4: =F4
A5: =CONCATENATE("NAME_TYPE_", UPPER(B5)) | B5: Poison | C5: どく | D5: =B5 | E5: Gift | F5: Veneno | G5: Veleno | H5: 독 | I5: =J5 | J5: 毒 | K5: =F5
A6: =CONCATENATE("NAME_TYPE_", UPPER(B6)) | B6: Ground | C6: じめん | D6: Sol | E6: Boden | F6: Tierra | G6: Terra | H6: 땅 | I6: =J6 | J6: 地面 | K6: =F6
A7: =CONCATENATE("NAME_TYPE_", UPPER(B7)) | B7: Rock | C7: いわ | D7: Roche | E7: Gestein | F7: Roca | G7: Roccia | H7: 바위 | I7: =J7 | J7: 岩石 | K7: =F7
A8: =CONCATENATE("NAME_TYPE_", UPPER(B8)) | B8: Bug | C8: むし | D8: Insecte | E8: Käfer | F8: Bicho | G8: Coleottero | H8: 벌레 | I8: =IFERROR(__xludf.DUMMYFUNCTION("GOOGLETRANSLATE(J8,""zh_HANS"",""zh_HANT"")"),"蟲") | J8: 虫 | K8: =F8
A9: =CONCATENATE("NAME_TYPE_", UPPER(B9)) | B9: Ghost | C9: ゴースト | D9: Spectre | E9: Geist | F9: Fantasma | G9: Spettro | H9: 고스트 | I9: =IFERROR(__xludf.DUMMYFUNCTION("GOOGLETRANSLATE(J9,""zh_HANS"",""zh_HANT"")"),"幽靈") | J9: 幽灵 | K9: =F9
A10: =CONCATENATE("NAME_TYPE_", UPPER(B10)) | B10: Steel | C10: はがね | D10: Acier | E10: Stahl | F10: Acero | G10: Acciaio | H10: 강철 | I10: =IFERROR(__xludf.DUMMYFUNCTION("GOOGLETRANSLATE(J10,""zh_HANS"",""zh_HANT"")"),"鋼") | J10: 钢 | K10: =F10
A11: =CONCATENATE("NAME_TYPE_", UPPER(B11)) | B11: Fire | C11: ほのお | D11: Feu | E11: Feuer | F11: Fuego | G11: Fuoco | H11: 불꽃 | I11: 火 | J11: =I11 | K11: =F11
A12: =CONCATENATE("NAME_TYPE_", UPPER(B12)) | B12: Water | C12: みず | D12: Eau | E12: Wasser | F12: Agua | G12: Acqua | H12: 물 | I12: 水 | J12: =I12 | K12: =F12
A13: =CONCATENATE("NAME_TYPE_", UPPER(B13)) | B13: Grass | C13: くさ | D13: Plante | E13: Pflanze | F13: Planta | G13: Erba | H13: 풀 | I13: 草 | J13: =I13 | K13: =F13
A14: =CONCATENATE("NAME_TYPE_", UPPER(B14)) | B14: Electric | C14: でんき | D14: Électrik | E14: Elektro | F14: Eléctrico | G14: Elettro | H14: 전기 | I14: =IFERROR(__xludf.DUMMYFUNCTION("GOOGLETRANSLATE(J14,""zh_HANS"",""zh_HANT"")"),"電") | J14: 电 | K14: =F14
A15: =CONCATENATE("NAME_TYPE_", UPPER(B15)) | B15: Psychic | C15: エスパー | D15: Psy | E15: Psyscho | F15: Psíquico | G15: Psico | H15: 에스퍼 | I15: =J15 | J15: 超能力 | K15: =F15
A16: =CONCATENATE("NAME_TYPE_", UPPER(B16)) | B16: Ice | C16: こおり | D16: Glace | E16: Eis | F16: Hielo | G16: Ghiaccio | H16: 얼음 | I16: =J16 | J16: 冰 | K16: =F16
A17: =CONCATENATE("NAME_TYPE_", UPPER(B17)) | B17: Dragon | C17: ドラゴン | D17: =B17 | E17: Drache | F17: Dragón | G17: Drago | H17: 드개곤 | I17: =IFERROR(__xludf.DUMMYFUNCTION("GOOGLETRANSLATE(J17,""zh_HANS"",""zh_HANT"")"),"龍") | J17: 龙 | K17: =F17
A18: =CONCATENATE("NAME_TYPE_", UPPER(B18)) | B18: Dark | C18: あく | D18: Ténèbres | E18: Unlicht | F18: Siniestro | G18: Buio | H18: 악 | I18: =IFERROR(__xludf.DUMMYFUNCTION("GOOGLETRANSLATE(J18,""zh_HANS"",""zh_HANT"")"),"惡") | J18: 恶 | K18: =F18
A19: =CONCATENATE("NAME_TYPE_", UPPER(B19)) | B19: Fairy | C19: フェアリ | D19: Fée | E19: Fee | F19: Hada | G19: Folletto | H19: 페어리 | I19: =J19 | J19: 妖精 | K19: =F19
A20: =CONCATENATE("NAME_TYPE_", UPPER(B20)) | B20: Stellar | C20: ステラ | D20: Stellaire | E20: =B20 | F20: Astral | G20: =CONCATENATE(F20,"e") | H20: 스텔라 | I20: 星晶 | J20: =I20 | K20: =F20

Sheet Moves
A1: =Pokemon!A1 | B1: =Pokemon!B1 | C1: =Pokemon!C1 | D1: =Pokemon!D1 | E1: =Pokemon!E1 | F1: =Pokemon!F1 | G1: =Pokemon!G1 | H1: =Pokemon!H1 | ... K1: =Pokemon!K1
A2: =CONCATENATE("NAME_MOVE_", SUBSTITUTE(UPPER(B2), " ", "")) | B2: Pound | C2: はたく | D2: Écras'Face | E2: Klaps | F2: Destructor | G2: Botta | H2: 막치기 | I2: 拍擊 | J2: =IFERROR(__xludf.DUMMYFUNCTION("GOOGLETRANSLATE(I2,""zh_HANT"",""zh_HANS"")"),"拍击") | K2: =F2
A3: =CONCATENATE("NAME_MOVE_", SUBSTITUTE(UPPER(B3), " ", "")) | B3: Karate Chop | C3: からてチョップ | D3: Poing Karaté | E3: Karateschlag | F3: Golpe Kárate | G3: Colpo Karate | H3: 태권당수 | I3: 空手劈 | J3: =I3 | K3: =F3
A4: =CONCATENATE("NAME_MOVE_", SUBSTITUTE(UPPER(B4), " ", "")) | B4: Double Slap | C4: おうふくビンタ | D4: Torgnoles | E4: Duplexhieb | F4: Doble Bofetón | G4: Doppiasberla | H4: 연속뺨치기 | I4: 連環巴掌 | J4: =IFERROR(__xludf.DUMMYFUNCTION("GOOGLETRANSLATE(I4,""zh_HANT"",""zh_HANS"")"),"连环巴掌") | K4: =F4
A5: =CONCATENATE("NAME_MOVE_", SUBSTITUTE(UPPER(B5), " ", "")) | B5: Comet Punch | C5: れんぞくパンチ | D5: Poing Comète | E5: Kometenhieb | F5: Puño Cometa | G5: Cometapugno | H5: 연속펀치 | I5: 連續拳 | J5: =IFERROR(__xludf.DUMMYFUNCTION("GOOGLETRANSLATE(I5,""zh_HANT"",""zh_HANS"")"),"连续拳") | K5: =F5
A6: =CONCATENATE("NAME_MOVE_", SUBSTITUTE(UPPER(B6), " ", "")) | B6: Mega Punch | C6: メガトンパンチ | D6: Ultimapoing | E6: Megahieb | F6: Megapuño | G6: Megapugno | H6: 메가톤펀치 | I6: 百萬噸重拳 | J6: =IFERROR(__xludf.DUMMYFUNCTION("GOOGLETRANSLATE(I6,""zh_HANT"",""zh_HANS"")"),"百万吨重拳") | K6: =F6
A7: =CONCATENATE("NAME_MOVE_", SUBSTITUTE(UPPER(B7), " ", "")) | B7: Pay Day | C7: ネコにこばん | D7: Jackpot | E7: Zahltag | F7: Día de Pago | G7: Giornopaga | H7: 고양이돈받기 | I7: 聚寶功 | J7: =IFERROR(__xludf.DUMMYFUNCTION("GOOGLETRANSLATE(I7,""zh_HANT"",""zh_HANS"")"),"聚宝功") | K7: =F7
A8: =CONCATENATE("NAME_MOVE_", SUBSTITUTE(UPPER(B8), " ", "")) | B8: Fire Punch | C8: ほのおのパンチ | D8: Poing Feu | E8: Feuerschlag | F8: Puño Fuego | G8: Fuocopugno | H8: 불꽃펀치 | I8: 火焰拳 | J8: =I8 | K8: =F8
A9: =CONCATENATE("NAME_MOVE_", SUBSTITUTE(UPPER(B9), " ", "")) | B9: Ice Punch | C9: らいとうパンチ | D9: Poing Glace | E9: Eishieb | F9: Puño Hielo | G9: Gelopugno | H9: 냉동펀치 | I9: 冰凍拳 | J9: =IFERROR(__xludf.DUMMYFUNCTION("GOOGLETRANSLATE(I9,""zh_HANT"",""zh_HANS"")"),"冰冻拳") | K9: =F9
A10: =CONCATENATE("NAME_MOVE_", SUBSTITUTE(UPPER(B10), " ", "")) | B10: Thunder Punch | C10: かみなりパンチ | D10: Poing Éclair | E10: Donnerschlag | F10: Puño Trueno | G10: Tuonopugno | H10: 번개펀치 | I10: 雷電拳 | J10: =IFERROR(__xludf.DUMMYFUNCTION("GOOGLETRANSLATE(I10,""zh_HANT"",""zh_HANS"")"),"雷电拳") | K10: =F10
A11: =CONCATENATE("NAME_MOVE_", SUBSTITUTE(UPPER(B11), " ", "")) | B11: Scratch | C11: ひっかく | D11: Griffe | E11: Kratzer | F11: Arañazo | G11: Graffio | H11: 할퀴기 | I11: 抓 | J11: =I11 | K11: =F11
A12: =CONCATENATE("NAME_MOVE_", SUBSTITUTE(UPPER(B12), " ", "")) | B12: Vise Grip | C12: はさむ | D12: Force Poigne | E12: Klammer | F12: Agarre | G12: Presa | H12: 찝기 | I12: 夾住 | J12: =IFERROR(__xludf.DUMMYFUNCTION("GOOGLETRANSLATE(I12,""zh_HANT"",""zh_HANS"")"),"夹住") | K12: =F12
A13: =CONCATENATE("NAME_MOVE_", SUBSTITUTE(UPPER(B13), " ", "")) | B13: Guillotine | C13: はさみギロチン | D13: =B13 | E13: =B13 | F13: Guillotina | G13: Ghigliottina | H13: 가위자르기 | I13: 斷頭鉗 | J13: 极落钳 | K13: =F13
A14: =CONCATENATE("NAME_MOVE_", SUBSTITUTE(UPPER(B14), " ", "")) | B14: Razor Wind | C14: かまいたち | D14: Coupe-Vent | E14: Klingensturm | F14: Viento Cortante | G14: Ventagliente | H14: 칼바람 | I14: 旋風刀 | J14: =IFERROR(__xludf.DUMMYFUNCTION("GOOGLETRANSLATE(I14,""zh_HANT"",""zh_HANS"")"),"旋风刀") | K14: =F14
A15: =CONCATENATE("NAME_MOVE_", SUBSTITUTE(UPPER(B15), " ", "")) | B15: Swords Dance | C15: つるぎのまい | D15: Danse-Lames | E15: Schwerttanz | F15: Danza Espada | G15: =SUBSTITUTE(F15," E","") | H15: 칼춤 | I15: 劍舞 | J15: =IFERROR(__xludf.DUMMYFUNCTION("GOOGLETRANSLATE(I15,""zh_HANT"",""zh_HANS"")"),"剑舞") | K15: =F15
A16: =CONCATENATE("NAME_MOVE_", SUBSTITUTE(UPPER(B16), " ", "")) | B16: Cut | C16: いあいぎり | D16: Coupe | E16: Zerschneider | F16: Corte | G16: Taglio | H16: 풀베기 | I16: 居合斬 | J16: 居合劈 | K16: =F16
A17: =CONCATENATE("NAME_MOVE_", SUBSTITUTE(UPPER(B17), " ", "")) | B17: Gust | C17: かざおこし | D17: Tornade | E17: Windstoß | F17: Tornado | G17: Raffica | H17: 바람일으키기 | I17: 起風 | J17: =IFERROR(__xludf.DUMMYFUNCTION("GOOGLETRANSLATE(I17,""zh_HANT"",""zh_HANS"")"),"起风") | K17: =F17
A18: =CONCATENATE("NAME_MOVE_", SUBSTITUTE(UPPER(B18), " ", "")) | B18: Wing Attack | C18: つばさでうつ | D18: Cru-Ailes | E18: Flügelschlag | F18: Ataque Ala | G18: Attacco d'Ala | H18: 날개치기 | I18: 翅膀攻擊 | J18: =IFERROR(__xludf.DUMMYFUNCTION("GOOGLETRANSLATE(I18,""zh_HANT"",""zh_HANS"")"),"翅膀攻击") | K18: =F18
A19: =CONCATENATE("NAME_MOVE_", SUBSTITUTE(UPPER(B19), " ", "")) | B19: Whirlwind | C19: ふきとばし | D19: Cyclone | E19: Wirbelwind | F19: Remolino | G19: Turbine | H19: 날려버리기 | I19: 吹飛 | J19: =IFERROR(__xludf.DUMMYFUNCTION("GOOGLETRANSLATE(I19,""zh_HANT"",""zh_HANS"")"),"吹飞") | K19: =F19
A20: =CONCATENATE("NAME_MOVE_", SUBSTITUTE(UPPER(B20), " ", "")) | B20: Fly | C20: そらをとぶ | D20: Vol | E20: Fliegen | F20: Vuelo | G20: Volo | H20: 공중날기 | I20: 飛翔 | J20: =IFERROR(__xludf.DUMMYFUNCTION("GOOGLETRANSLATE(I20,""zh_HANT"",""zh_HANS"")"),"飞翔") | K20: =F20
A21: =CONCATENATE("NAME_MOVE_", SUBSTITUTE(UPPER(B21), " ", "")) | B21: Bind | C21: しみつける | D21: Étreinte | E21: Klammergriff | F21: Atadura | G21: Legatutto | H21: 조이기 | I21: 綁緊 | J21: =IFERROR(__xludf.DUMMYFUNCTION("GOOGLETRANSLATE(I21,""zh_HANT"",""zh_HANS"")"),"绑紧") | K21: =F21
A22: =CONCATENATE("NAME_MOVE_", SUBSTITUTE(UPPER(B22), " ", "")) | B22: Slam | C22: たたけつける | D22: Souplesse | E22: =B22 | F22: Atizar | G22: Schianto | H22: 힘껏치기 | I22: 摔打 | J22: =I22 | K22: =F22
A23: =CONCATENATE("NAME_MOVE_", SUBSTITUTE(UPPER(B23), " ", "")) | B23: Vine Whip | C23: つるのむち | D23: Fouet Lianes | E23: Rankenhieb | F23: Látigo Cepa | G23: Frustata | H23: 덩굴채찍 | I23: 藤鞭 | J23: =I23 | K23: =F23
A24: =CONCATENATE("NAME_MOVE_", SUBSTITUTE(UPPER(B24), " ", "")) | B24: Stomp | C24: ふみつけ | D24: Écrasement | E24: Stampfer | F24: Pisotón | G24: Pestone | H24: 짓밟기 | I24: 藤鞭 | J24: =I24 | K24: =F24
A25: =CONCATENATE("NAME_MOVE_", SUBSTITUTE(UPPER(B25), " ", "")) | B25: Double Kick | C25: にどげり | D25: Double Pied | E25: Doppelkick | F25: Doble Patada | G25: Doppiocalcio | H25: 두번치기 | I25: 二連踢 | J25: =IFERROR(__xludf.DUMMYFUNCTION("GOOGLETRANSLATE(I25,""zh_HANT"",""zh_HANS"")"),"二连踢") | K25: =F25
A26: =CONCATENATE("NAME_MOVE_", SUBSTITUTE(UPPER(B26), " ", "")) | B26: Mega Kick | C26: メガトンキック | D26: Ultimawashi | E26: Megakick | F26: Megapatada | G26: Megacalcio | H26: 메가톤킥 | I26: 百萬噸重踢 | J26: =IFERROR(__xludf.DUMMYFUNCTION("GOOGLETRANSLATE(I26,""zh_HANT"",""zh_HANS"")"),"百万吨重踢") | K26: =F26
A27: =CONCATENATE("NAME_MOVE_", SUBSTITUTE(UPPER(B27), " ", "")) | B27: Jump Kick | C27: とびげり | D27: Pied Sauté | E27: Sprungkick | F27: Patada Salto | G27: Calciosalto | H27: 점프킥 | I27: 飛踢 | J27: =IFERROR(__xludf.DUMMYFUNCTION("GOOGLETRANSLATE(I27,""zh_HANT"",""zh_HANS"")"),"飞踢") | K27: =F27
A28: =CONCATENATE("NAME_MOVE_", SUBSTITUTE(UPPER(B28), " ", "")) | B28: Rolling Kick | C28: まわしげり | D28: Mawashi Geri | E28: Fegekick | F28: Patada Giro | G28: Calciorullo | H28: 돌려차기 | I28: 迴旋踢 | J28: =IFERROR(__xludf.DUMMYFUNCTION("GOOGLETRANSLATE(I28,""zh_HANT"",""zh_HANS"")"),"回旋踢") | K28: =F28
A29: =CONCATENATE("NAME_MOVE_", SUBSTITUTE(UPPER(B29), " ", "")) | B29: Sand Attack | C29: すなかけ | D29: Jet de Sable | E29: Sandwirbel | F29: Ataque Arena | G29: Turbosabbia | H29: 모래뿌리기 | I29: 潑沙 | J29: =IFERROR(__xludf.DUMMYFUNCTION("GOOGLETRANSLATE(I29,""zh_HANT"",""zh_HANS"")"),"泼沙") | K29: =F29
A30: =CONCATENATE("NAME_MOVE_", SUBSTITUTE(UPPER(B30), " ", "")) | B30: Headbutt | C30: ずつき | D30: Coup d'Boule | E30: Kopfnuss | F30: Golpe Cabeza | G30: Bottintesta | H30: 박치기 | I30: 頭錘 | J30: =IFERROR(__xludf.DUMMYFUNCTION("GOOGLETRANSLATE(I30,""zh_HANT"",""zh_HANS"")"),"头锤") | K30: =F30
A31: =CONCATENATE("NAME_MOVE_", SUBSTITUTE(UPPER(B31), " ", "")) | B31: Horn Attack | C31: つのでつく | D31: Koud'Korne | E31: Hornattacke | F31: Cornada | G31: Incornata | H31: 뿔찌르기 | I31: 角撞 | J31: =I31 | K31: =F31
A32: =CONCATENATE("NAME_MOVE_", SUBSTITUTE(UPPER(B32), " ", "")) | B32: Fury Attack | C32: みだれづき | D32: Furie | E32: Furienschlag | F32: Ataque Furia | G32: Furia | H32: 마구찌르기 | I32: 亂擊 | J32: =IFERROR(__xludf.DUMMYFUNCTION("GOOGLETRANSLATE(I32,""zh_HANT"",""zh_HANS"")"),"乱击") | K32: =F32
A33: =CONCATENATE("NAME_MOVE_", SUBSTITUTE(UPPER(B33), " ", "")) | B33: Horn Drill | C33: つのドリル | D33: Empal'Korne | E33: Hornbohrer | F33: Perforador | G33: Perforcorno | H33: 뿔드릴 | I33: 角鑽 | J33: =IFERROR(__xludf.DUMMYFUNCTION("GOOGLETRANSLATE(I33,""zh_HANT"",""zh_HANS"")"),"角钻") | K33: =F33
A34: =CONCATENATE("NAME_MOVE_", SUBSTITUTE(UPPER(B34), " ", "")) | B34: Tackle | C34: たいあたり | D34: Charge | E34: =B34 | F34: Placaje | G34: Azione | H34: 몸통박치기 | I34: 撞擊 | J34: =IFERROR(__xludf.DUMMYFUNCTION("GOOGLETRANSLATE(I34,""zh_HANT"",""zh_HANS"")"),"撞击") | K34: =F34
A35: =CONCATENATE("NAME_MOVE_", SUBSTITUTE(UPPER(B35), " ", "")) | B35: Body Slam | C35: のしかかり | D35: Plaquage | E35: Bodyslam | F35: Golpe Cuerpo | G35: Corposcontro | H35: 누르기 | I35: 泰山壓頂 | J35: =IFERROR(__xludf.DUMMYFUNCTION("GOOGLETRANSLATE(I35,""zh_HANT"",""zh_HANS"")"),"泰山压顶") | K35: =F35
A36: =CONCATENATE("NAME_MOVE_", SUBSTITUTE(UPPER(B36), " ", "")) | B36: Wrap | C36: まきつく | D36: Ligotage | E36: Wickel | F36: Constricción | G36: Avvolgibotta | H36: 김밥말이 | I36: 緊束 | J36: =IFERROR(__xludf.DUMMYFUNCTION("GOOGLETRANSLATE(I36,""zh_HANT"",""zh_HANS"")"),"紧束") | K36: =F36
A37: =CONCATENATE("NAME_MOVE_", SUBSTITUTE(UPPER(B37), " ", "")) | B37: Take Down | C37: とっしん | D37: Bélier | E37: Bodycheck | F37: Derribo | G37: Riduttore | H37: 돌진 | I37: 猛撞 | J37: =I37 | K37: =F37
A38: =CONCATENATE("NAME_MOVE_", SUBSTITUTE(UPPER(B38), " ", "")) | B38: Thrash | C38: あばれる | D38: Mania | E38: Fuchtler | F38: Golpe | G38: Colpo | H38: 난동부리기 | I38: 大鬧一番 | J38: =IFERROR(__xludf.DUMMYFUNCTION("GOOGLETRANSLATE(I38,""zh_HANT"",""zh_HANS"")"),"大闹一番") | K38: =F38
A39: =CONCATENATE("NAME_MOVE_", SUBSTITUTE(SUBSTITUTE(UPPER(B39), " ", ""), "-", "")) | B39: Double-Edge | C39: すてみッタク | D39: Damoclès | E39: Risikotackle | F39: Doble Filo | G39: Sdoppiatore | H39: 이판사판태클 | I39: 捨身衝撞 | J39: =IFERROR(__xludf.DUMMYFUNCTION("GOOGLETRANSLATE(I39,""zh_HANT"",""zh_HANS"")"),"舍身冲撞") | K39: =F39
A40: =CONCATENATE("NAME_MOVE_", SUBSTITUTE(SUBSTITUTE(UPPER(B40), " ", ""), "-", "")) | B40: Tail Whip | C40: しっぽをふる | D40: Mimi-Queue | E40: Rutenschlag | F40: Látigo | G40: Colpocoda | H40: 꼬리흔들기 | I40: 搖尾巴 | J40: =IFERROR(__xludf.DUMMYFUNCTION("GOOGLETRANSLATE(I40,""zh_HANT"",""zh_HANS"")"),"摇尾巴") | K40: =F40
...

Sheet Abilities
A1: =Pokemon!A1 | B1: =Pokemon!B1 | C1: =Pokemon!C1 | D1: =Pokemon!D1 | E1: =Pokemon!E1 | F1: =Pokemon!F1 | G1: =Pokemon!G1 | H1: =Pokemon!H1 | ... K1: =Pokemon!K1
A2: =CONCATENATE("NAME_ABILITY_", SUBSTITUTE(UPPER(B2), " ", "")) | B2: Stench | C2: あくしゅう | D2: Puanteur | E2: Duftnote | F2: Hedor | G2: Tanfo | H2: 악취 | I2: 惡臭 | J2: =IFERROR(__xludf.DUMMYFUNCTION("GOOGLETRANSLATE(I2,""zh_HANT"",""zh_HANS"")"),"恶臭") | K2: =F2
A3: =CONCATENATE("NAME_ABILITY_", SUBSTITUTE(UPPER(B3), " ", "")) | B3: Drizzle | C3: あめふらし | D3: Crachin | E3: Niesel | F3: Llovizna | G3: Piovischio | H3: 잔비 | I3: 降雨 | J3: =I3 | K3: =F3
A4: =CONCATENATE("NAME_ABILITY_", SUBSTITUTE(UPPER(B4), " ", "")) | B4: Speed Boost | C4: かそく | D4: Turbo | E4: Temposchub | F4: Impulso | G4: Acceleratore | H4: 가속 | I4: 加速 | J4: =I4 | K4: =F4
A5: =CONCATENATE("NAME_ABILITY_", SUBSTITUTE(UPPER(B5), " ", "")) | B5: Battle Armor | C5: カブトアーマー | D5: Armurbaston | E5: Kampfpanzer | F5: Armadura Batalla | G5: Lottascudo | H5: 전투 무장 | I5: 戰鬥盔甲 | J5: =IFERROR(__xludf.DUMMYFUNCTION("GOOGLETRANSLATE(I5,""zh_HANT"",""zh_HANS"")"),"战斗盔甲") | K5: =F5
A6: =CONCATENATE("NAME_ABILITY_", SUBSTITUTE(UPPER(B6), " ", "")) | B6: Sturdy | C6: がんじょう | D6: Fermeté | E6: Robustheit | F6: Robustez | G6: Vigore | H6: 옹골참 | I6: 結實 | J6: =IFERROR(__xludf.DUMMYFUNCTION("GOOGLETRANSLATE(I6,""zh_HANT"",""zh_HANS"")"),"结实") | K6: =F6
A7: =CONCATENATE("NAME_ABILITY_", SUBSTITUTE(UPPER(B7), " ", "")) | B7: Damp | C7: しめりけ | D7: Moiteur | E7: Feuchtigkeit | F7: Humedad | G7: Umidità | H7: 습기 | I7: 濕氣 | J7: =IFERROR(__xludf.DUMMYFUNCTION("GOOGLETRANSLATE(I7,""zh_HANT"",""zh_HANS"")"),"湿气") | K7: =F7
A8: =CONCATENATE("NAME_ABILITY_", SUBSTITUTE(UPPER(B8), " ", "")) | B8: Limber | C8: じゅうなん | D8: Échauffement | E8: Flexibilität | F8: Flexibilidad | G8: Scioltezza | H8: 유연 | I8: 柔軟 | J8: =IFERROR(__xludf.DUMMYFUNCTION("GOOGLETRANSLATE(I8,""zh_HANT"",""zh_HANS"")"),"柔软") | K8: =F8
A9: =CONCATENATE("NAME_ABILITY_", SUBSTITUTE(UPPER(B9), " ", "")) | B9: Sand Veil | C9: すながくれ | D9: Voile Sable | E9: Sandschleier | F9: Velo Arena | G9: Sabbiavelo | H9: 모래숨기 | I9: 沙隱 | J9: =IFERROR(__xludf.DUMMYFUNCTION("GOOGLETRANSLATE(I9,""zh_HANT"",""zh_HANS"")"),"沙隐") | K9: =F9
A10: =CONCATENATE("NAME_ABILITY_", SUBSTITUTE(UPPER(B10), " ", "")) | B10: Static | C10: せいでんき | D10: Statik | E10: =D10 | F10: Elec. Estática | G10: =CONCATENATE(B10,"o") | H10: 정전기 | I10: 靜電 | J10: =IFERROR(__xludf.DUMMYFUNCTION("GOOGLETRANSLATE(I10,""zh_HANT"",""zh_HANS"")"),"静电") | K10: =F10
A11: =CONCATENATE("NAME_ABILITY_", SUBSTITUTE(UPPER(B11), " ", "")) | B11: Volt Absorb | C11: ちくでん | D11: Absorbe-Volt | E11: Voltabsorber | F11: Absorbe Elec. | G11: Assorbivolt | H11: 축전 | I11: 蓄電 | J11: =IFERROR(__xludf.DUMMYFUNCTION("GOOGLETRANSLATE(I11,""zh_HANT"",""zh_HANS"")"),"蓄电") | K11: =F11
A12: =CONCATENATE("NAME_ABILITY_", SUBSTITUTE(UPPER(B12), " ", "")) | B12: Water Absorb | C12: ちょすい | D12: Absorbe-Eau | E12: H2O-Absorber | F12: Absorbe Agua | G12: Assorbacqua | H12: 저수 | I12: 儲水 | J12: =IFERROR(__xludf.DUMMYFUNCTION("GOOGLETRANSLATE(I12,""zh_HANT"",""zh_HANS"")"),"储水") | K12: =F12
A13: =CONCATENATE("NAME_ABILITY_", SUBSTITUTE(UPPER(B13), " ", "")) | B13: Oblivious | C13: どんかん | D13: Benêt | E13: Dösigkeit | F13: Despiste | G13: Indifferenza | H13: 둔감 | I13: 遲鈍 | J13: =IFERROR(__xludf.DUMMYFUNCTION("GOOGLETRANSLATE(I13,""zh_HANT"",""zh_HANS"")"),"迟钝") | K13: =F13
A14: =CONCATENATE("NAME_ABILITY_", SUBSTITUTE(UPPER(B14), " ", "")) | B14: Cloud Nine | C14: ノーてんき | D14: Ciel Gris | E14: Wolke Sieben | F14: Aclimatación | G14: Antimeteo | H14: 날씨 부정 | I14: 無關天氣 | J14: =IFERROR(__xludf.DUMMYFUNCTION("GOOGLETRANSLATE(I14,""zh_HANT"",""zh_HANS"")"),"无关天气") | K14: =F14
A15: =CONCATENATE("NAME_ABILITY_", SUBSTITUTE(UPPER(B15), " ", "")) | B15: Compund Eyes | C15: ふくがん | D15: Oeil Composé | E15: Facettenauge | F15: Ojo Compuesto | G15: Insettochi | H15: 복안 | I15: 複眼 | J15: =IFERROR(__xludf.DUMMYFUNCTION("GOOGLETRANSLATE(I15,""zh_HANT"",""zh_HANS"")"),"复眼") | K15: =F15
A16: =CONCATENATE("NAME_ABILITY_", SUBSTITUTE(UPPER(B16), " ", "")) | B16: Insomia | C16: ふみん | D16: =B16 | E16: =B16 | F16: Insomnio | G16: Insonnia | H16: 불면 | I16: 不眠 | J16: =I16 | K16: =F16
A17: =CONCATENATE("NAME_ABILITY_", SUBSTITUTE(UPPER(B17), " ", "")) | B17: Color Change | C17: へんしょく | D17: Homochromie | E17: Farbwechsel | F17: Cambio Color | G17: Cambiacolore | H17: 변색 | I17: 變色 | J17: =IFERROR(__xludf.DUMMYFUNCTION("GOOGLETRANSLATE(I17,""zh_HANT"",""zh_HANS"")"),"变色") | K17: =F17
A18: =CONCATENATE("NAME_ABILITY_", SUBSTITUTE(UPPER(B18), " ", "")) | B18: Immunity | C18: めんえき | D18: Vaccin | E18: Immunität | F18: Inmunidad | G18: Immunità | H18: 면역 | I18: 免疫 | J18: =I18 | K18: =F18
A19: =CONCATENATE("NAME_ABILITY_", SUBSTITUTE(UPPER(B19), " ", "")) | B19: Flash Fire | C19: もらいび | D19: Torche | E19: Feuerfänger | F19: Absorbe Fuego | G19: Fuocardore | H19: 타오르는 불꽃 | I19: 引火 | J19: =I19 | K19: =F19
A20: =CONCATENATE("NAME_ABILITY_", SUBSTITUTE(UPPER(B20), " ", "")) | B20: Shield Dust | C20: りんぷん | D20: Écran Poudre | E20: Puderabwehr | F20: Polvo Escudo | G20: Polvoscudo | H20: 인분 | I20: 鱗粉 | J20: =IFERROR(__xludf.DUMMYFUNCTION("GOOGLETRANSLATE(I20,""zh_HANT"",""zh_HANS"")"),"鳞粉") | K20: =F20
A21: =CONCATENATE("NAME_ABILITY_", SUBSTITUTE(UPPER(B21), " ", "")) | B21: Own Tempo | C21: マイペース | D21: Tempo Perso | E21: Tempomacher | F21: Ritmo Propio | G21: Mente Locale | H21: 마이페이스 | I21: 我行我素 | J21: =I21 | K21: =F21
A22: =CONCATENATE("NAME_ABILITY_", SUBSTITUTE(UPPER(B22), " ", "")) | B22: Suction Cups | C22: きゅうばん | D22: Ventouse | E22: Saugnapf | F22: Ventosas | G22: Ventose | H22: 흡반 | I22: 吸盤 | J22: =IFERROR(__xludf.DUMMYFUNCTION("GOOGLETRANSLATE(I22,""zh_HANT"",""zh_HANS"")"),"吸盘") | K22: =F22
A23: =CONCATENATE("NAME_ABILITY_", SUBSTITUTE(UPPER(B23), " ", "")) | B23: Intimidate | C23: いかく | D23: Intimidation | E23: Bedroher | F23: Intimidación | G23: Prepotenza | H23: 위협 | I23: 威嚇 | J23: =IFERROR(__xludf.DUMMYFUNCTION("GOOGLETRANSLATE(I23,""zh_HANT"",""zh_HANS"")"),"威吓") | K23: =F23
A24: =CONCATENATE("NAME_ABILITY_", SUBSTITUTE(UPPER(B24), " ", "")) | B24: Shadow Tag | C24: かげふみ | D24: Marque Ombre | E24: Wegsperre | F24: Sombra Trampa | G24: Pedinombra | H24: 그림자 밟기 | I24: 踩影 | J24: =I24 | K24: =F24
A25: =CONCATENATE("NAME_ABILITY_", SUBSTITUTE(UPPER(B25), " ", "")) | B25: Rough Skin | C25: さめはだ | D25: Peau Dure | E25: Rauhaut | F25: Piel Tosca | G25: Cartavetro | H25: 까칠한 피부 | I25: 粗糙皮膚 | J25: =IFERROR(__xludf.DUMMYFUNCTION("GOOGLETRANSLATE(I25,""zh_HANT"",""zh_HANS"")"),"粗糙皮肤") | K25: =F25
A26: =CONCATENATE("NAME_ABILITY_", SUBSTITUTE(UPPER(B26), " ", "")) | B26: Wonder Guard | C26: ふしぎなまもり | D26: Garde Mystik | E26: Wunderwache | F26: Superguarda | G26: Magidifesa | H26: 불가사의 부적 | I26: 神奇守護 | J26: =IFERROR(__xludf.DUMMYFUNCTION("GOOGLETRANSLATE(I26,""zh_HANT"",""zh_HANS"")"),"神奇守护") | K26: =F26
A27: =CONCATENATE("NAME_ABILITY_", SUBSTITUTE(UPPER(B27), " ", "")) | B27: Levitate | C27: ふゆう | D27: Lévitation | E27: Schwebe | F27: Levitación | G27: Levitazione | H27: 부유 | I27: 飄浮 | J27: =IFERROR(__xludf.DUMMYFUNCTION("GOOGLETRANSLATE(I27,""zh_HANT"",""zh_HANS"")"),"飘浮") | K27: =F27
A28: =CONCATENATE("NAME_ABILITY_", SUBSTITUTE(UPPER(B28), " ", "")) | B28: Effect Spore | C28: ほうし | D28: Pose Spore | E28: Sporenwirt | F28: Efecto Espora | G28: Spargispora | H28: 포자 | I28: 孢子 | J28: =I28 | K28: =F28
A29: =CONCATENATE("NAME_ABILITY_", SUBSTITUTE(UPPER(B29), " ", "")) | B29: Synchonize | C29: シンクロ | D29: Synchro | E29: =D29 | F29: Sincronía | G29: Sincronismo | H29: 싱크로 | I29: 同步 | J29: =I29 | K29: =F29
A30: =CONCATENATE("NAME_ABILITY_", SUBSTITUTE(UPPER(B30), " ", "")) | B30: Clear Body | C30: クリアボヂィ | D30: Corps Sain | E30: Neutraltorso | F30: Cuerpo Puro | G30: Corpochiaro | H30: 클리어 바디 | I30: 恆淨之軀 | J30: =IFERROR(__xludf.DUMMYFUNCTION("GOOGLETRANSLATE(I30,""zh_HANT"",""zh_HANS"")"),"恒净之躯") | K30: =F30
A31: =CONCATENATE("NAME_ABILITY_", SUBSTITUTE(UPPER(B31), " ", "")) | B31: Natural Cure | C31: しぜんかいふく | D31: Médic Nature | E31: Innere Kraft | F31: Cura Natural | G31: Alternacura | H31: 자연회복 | I31: 自然回復 | J31: =IFERROR(__xludf.DUMMYFUNCTION("GOOGLETRANSLATE(I31,""zh_HANT"",""zh_HANS"")"),"自然回复") | K31: =F31
A32: =CONCATENATE("NAME_ABILITY_", SUBSTITUTE(UPPER(B32), " ", "")) | B32: Lightning Rod | C32: ひらいしん | D32: Paratonnerre | E32: Blitzfänger | F32: Pararrayos | G32: Parafulmine | H32: 피뢰침 | I32: 避雷針 | J32: =IFERROR(__xludf.DUMMYFUNCTION("GOOGLETRANSLATE(I32,""zh_HANT"",""zh_HANS"")"),"避雷针") | K32: =F32
A33: =CONCATENATE("NAME_ABILITY_", SUBSTITUTE(UPPER(B33), " ", "")) | B33: Serene Grace | C33: てんのめぐみ | D33: Sérénité | E33: Edelmut | F33: Dicha | G33: Leggiadro | H33: 하늘의 은총 | I33: 天恩 | J33: =I33 | K33: =F33
A34: =CONCATENATE("NAME_ABILITY_", SUBSTITUTE(UPPER(B34), " ", "")) | B34: Swift Swim | C34: すいすい | D34: Glissade | E34: Wassertempo | F34: Nado Rápido | G34: Nuotovelox | H34: 쓱쓱 | I34: 悠游自如 | J34: =I34 | K34: =F34
A35: =CONCATENATE("NAME_ABILITY_", SUBSTITUTE(UPPER(B35), " ", "")) | B35: Chlorophyll | C35: ようりょくそ | D35: Chlorophylle | E35: =B35 | F35: Clorofila | G35: Clorofilla | H35: 엽록소 | I35: 葉綠素 | J35: =IFERROR(__xludf.DUMMYFUNCTION("GOOGLETRANSLATE(I35,""zh_HANT"",""zh_HANS"")"),"叶绿素") | K35: =F35
A36: =CONCATENATE("NAME_ABILITY_", SUBSTITUTE(UPPER(B36), " ", "")) | B36: Illuminate | C36: はっこう | D36: Lumiattirance | E36: Erleuchtung | F36: Iluminación | G36: Risplendi | H36: 발광 | I36: 發光 | J36: =IFERROR(__xludf.DUMMYFUNCTION("GOOGLETRANSLATE(I36,""zh_HANT"",""zh_HANS"")"),"发光") | K36: =F36
A37: =CONCATENATE("NAME_ABILITY_", SUBSTITUTE(UPPER(B37), " ", "")) | B37: Trace | C37: トレース | D37: Calque | E37: Fährte | F37: Rastro | G37: Traccia | H37: 트레이스 | I37: 複製 | J37: =IFERROR(__xludf.DUMMYFUNCTION("GOOGLETRANSLATE(I37,""zh_HANT"",""zh_HANS"")"),"克隆") | K37: =F37
A38: =CONCATENATE("NAME_ABILITY_", SUBSTITUTE(UPPER(B38), " ", "")) | B38: Huge Power | C38: ちからもち | D38: Coloforce | E38: Kraftkoloss | F38: Potencia | G38: Macroforza | H38: 천하장사 | I38: 大力士 | J38: =I38 | K38: =F38
A39: =CONCATENATE("NAME_ABILITY_", SUBSTITUTE(UPPER(B39), " ", "")) | B39: Poison Point | C39: どくのトゲ | D39: Point Poison | E39: Giftdorn | F39: Punto Tóxico | G39: Velenopunto | H39: 독가시 | I39: 毒刺 | J39: =I39 | K39: =F39
A40: =CONCATENATE("NAME_ABILITY_", SUBSTITUTE(UPPER(B40), " ", "")) | B40: Inner Focus | C40: せいしんりょく | D40: Attention | E40: Konzentrator | F40: Foco Interno | G40: Forza Interiore | H40: 정신력 | I40: 精神力 | J40: =I40 | K40: =F40
...

Sheet Natures
A1: =Pokemon!A1 | B1: =Pokemon!B1 | C1: =Pokemon!C1 | D1: =Pokemon!D1 | E1: =Pokemon!E1 | F1: =Pokemon!F1 | G1: =Pokemon!G1 | H1: =Pokemon!H1 | ... K1: =Pokemon!K1
A2: =CONCATENATE("NAME_NATURE_", UPPER(B2)) | B2: Adamant | C2: いじっぱり | D2: Rigide | E2: Hart | F2: Firme | G2: Decisa | H2: 고집 | I2: 固執 | J2: =IFERROR(__xludf.DUMMYFUNCTION("GOOGLETRANSLATE(I2,""zh_HANT"",""zh_HANS"")"),"固执") | K2: =F2
A3: =CONCATENATE("NAME_NATURE_", UPPER(B3)) | B3: Bashful | C3: てれや | D3: Pudique | E3: Zaghaft | F3: Tímida | G3: Ritrosa | H3: 수줍음 | I3: 害羞 | J3: =I3 | K3: =F3
A4: =CONCATENATE("NAME_NATURE_", UPPER(B4)) | B4: Bold | C4: ずぶとい | D4: Assuré | E4: Kühn | F4: Osada | G4: Sicura | H4: 대담 | I4: 大膽 | J4: =IFERROR(__xludf.DUMMYFUNCTION("GOOGLETRANSLATE(I4,""zh_HANT"",""zh_HANS"")"),"大胆") | K4: =F4
A5: =CONCATENATE("NAME_NATURE_", UPPER(B5)) | B5: Brave | C5: ゆうかん | D5: =B5 | E5: Mutig | F5: Audaz | G5: Audace | H5: 용감 | I5: 勇敢 | J5: =I5 | K5: =F5
A6: =CONCATENATE("NAME_NATURE_", UPPER(B6)) | B6: Calm | C6: おだやか | D6: Calme | E6: Still | F6: Serena | G6: Calma | H6: 차분 | I6: 溫和 | J6: =IFERROR(__xludf.DUMMYFUNCTION("GOOGLETRANSLATE(I6,""zh_HANT"",""zh_HANS"")"),"温和") | K6: =F6
A7: =CONCATENATE("NAME_NATURE_", UPPER(B7)) | B7: Careful | C7: しんちょう | D7: Prudent | E7: Sacht | F7: Cauta | G7: Cauta | H7: 신중 | I7: 慎重 | J7: =I7 | K7: =F7
A8: =CONCATENATE("NAME_NATURE_", UPPER(B8)) | B8: Docile | C8: すなお | D8: =B8 | E8: Sanft | F8: Dócil | G8: Docile | H8: 온순 | I8: 坦率 | J8: =I8 | K8: =F8
A9: =CONCATENATE("NAME_NATURE_", UPPER(B9)) | B9: Gentle | C9: おとなしい | D9: Gentil | E9: Zart | F9: Amable | G9: Gentile | H9: 얌전 | I9: 溫順 | J9: =IFERROR(__xludf.DUMMYFUNCTION("GOOGLETRANSLATE(I9,""zh_HANT"",""zh_HANS"")"),"温顺") | K9: =F9
A10: =CONCATENATE("NAME_NATURE_", UPPER(B10)) | B10: Hardy | C10: がんばりや | D10: Hardi | E10: Robust | F10: Fuerte | G10: Ardita | H10: 노력 | I10: 勤奮 | J10: =IFERROR(__xludf.DUMMYFUNCTION("GOOGLETRANSLATE(I10,""zh_HANT"",""zh_HANS"")"),"勤奋") | K10: =F10
A11: =CONCATENATE("NAME_NATURE_", UPPER(B11)) | B11: Hasty | C11: せっかち | D11: Pressé | E11: Hastig | F11: Activa | G11: Lesta | H11: 성급 | I11: 急躁 | J11: =I11 | K11: =F11
A12: =CONCATENATE("NAME_NATURE_", UPPER(B12)) | B12: Impish | C12: わんぱく | D12: Malin | E12: Pfiffig | F12: Agitada | G12: Scaltra | H12: 장난꾸러기 | I12: 淘氣 | J12: =IFERROR(__xludf.DUMMYFUNCTION("GOOGLETRANSLATE(I12,""zh_HANT"",""zh_HANS"")"),"淘气") | K12: =F12
A13: =CONCATENATE("NAME_NATURE_", UPPER(B13)) | B13: Jolly | C13: ようき | D13: Jovial | E13: Froh | F13: Alegre | G13: Allegra | H13: 명랑 | I13: 爽朗 | J13: =I13 | K13: =F13
A14: =CONCATENATE("NAME_NATURE_", UPPER(B14)) | B14: Lax | C14: のうてんき | D14: Lâche | E14: Lasch | F14: Floja | G14: Fiacca | H14: 촐랑 | I14: 樂天 | J14: =IFERROR(__xludf.DUMMYFUNCTION("GOOGLETRANSLATE(I14,""zh_HANT"",""zh_HANS"")"),"乐天") | K14: =F14
A15: =CONCATENATE("NAME_NATURE_", UPPER(B15)) | B15: Lonely | C15: さみしがり | D15: Solo | E15: =D15 | F15: Huraña | G15: Schiva | H15: 외로움 | I15: 怕寂寞 | J15: =I15 | K15: =F15
A16: =CONCATENATE("NAME_NATURE_", UPPER(B16)) | B16: Mild | C16: おっとり | D16: Doux | E16: =B16 | F16: Afable | G16: Mite | H16: 의젓 | I16: 慢吞吞 | J16: =I16 | K16: =F16
A17: =CONCATENATE("NAME_NATURE_", UPPER(B17)) | B17: Modest | C17: ひかえめ | D17: Modeste | E17: Mäßig | F17: Modesta | G17: Modesta | H17: 조심 | I17: 內斂 | J17: =IFERROR(__xludf.DUMMYFUNCTION("GOOGLETRANSLATE(I17,""zh_HANT"",""zh_HANS"")"),"内敛") | K17: =F17
A18: =CONCATENATE("NAME_NATURE_", UPPER(B18)) | B18: Naive | C18: むじゃき | D18: Naïf | E18: Naiv | F18: Ingenua | G18: Ingenua | H18: 천진난만 | I18: 天真 | J18: =I18 | K18: =F18
A19: =CONCATENATE("NAME_NATURE_", UPPER(B19)) | B19: Naughty | C19: やんちゃ | D19: Mauvais | E19: Frech | F19: Pícara | G19: Birbona | H19: 개구쟁이 | I19: 頑皮 | J19: =IFERROR(__xludf.DUMMYFUNCTION("GOOGLETRANSLATE(I19,""zh_HANT"",""zh_HANS"")"),"顽皮") | K19: =F19
A20: =CONCATENATE("NAME_NATURE_", UPPER(B20)) | B20: Quiet | C20: れいせい | D20: Discret | E20: Ruhig | F20: Mansa | G20: Quieta | H20: 냉정 | I20: 冷靜 | J20: =IFERROR(__xludf.DUMMYFUNCTION("GOOGLETRANSLATE(I20,""zh_HANT"",""zh_HANS"")"),"冷静") | K20: =F20
A21: =CONCATENATE("NAME_NATURE_", UPPER(B21)) | B21: Quirky | C21: きまぐれ | D21: Bizarre | E21: Kauzig | F21: Rara | G21: Furba | H21: 변덕 | I21: 浮躁 | J21: =I21 | K21: =F21
A22: =CONCATENATE("NAME_NATURE_", UPPER(B22)) | B22: Rash | C22: うっかりや | D22: Foufou | E22: Hitzig | F22: Alocada | G22: Ardente | H22: 덜렁 | I22: 馬虎 | J22: =IFERROR(__xludf.DUMMYFUNCTION("GOOGLETRANSLATE(I22,""zh_HANT"",""zh_HANS"")"),"马虎") | K22: =F22
A23: =CONCATENATE("NAME_NATURE_", UPPER(B23)) | B23: Relaxed | C23: のんき | D23: Relax | E23: Locker | F23: Plácida | G23: Placida | H23: 무사태평 | I23: 悠閒 | J23: =IFERROR(__xludf.DUMMYFUNCTION("GOOGLETRANSLATE(I23,""zh_HANT"",""zh_HANS"")"),"悠闲") | K23: =F23
A24: =CONCATENATE("NAME_NATURE_", UPPER(B24)) | B24: Sassy | C24: なまいき | D24: Malpoli | E24: Forsch | F24: Grosera | G24: Vivace | H24: 건방 | I24: 自大 | J24: =I24 | K24: =F24
A25: =CONCATENATE("NAME_NATURE_", UPPER(B25)) | B25: Serious | C25: まじめ | D25: Sérieux | E25: Ernst | F25: Seria | G25: Seria | H25: 성실 | I25: 認真 | J25: =IFERROR(__xludf.DUMMYFUNCTION("GOOGLETRANSLATE(I25,""zh_HANT"",""zh_HANS"")"),"认真") | K25: =F25
A26: =CONCATENATE("NAME_NATURE_", UPPER(B26)) | B26: Timid | C26: おくびょう | D26: Timide | E26: Scheu | F26: Miedosa | G26: Timida | H26: 겁쟁이 | I26: 膽小 | J26: =IFERROR(__xludf.DUMMYFUNCTION("GOOGLETRANSLATE(I26,""zh_HANT"",""zh_HANS"")"),"胆小") | K26: =F26

Sheet Characteristics
A1: =Pokemon!A1 | B1: =Pokemon!B1 | C1: =Pokemon!C1 | D1: =Pokemon!D1 | E1: =Pokemon!E1 | F1: =Pokemon!F1 | G1: =Pokemon!G1 | H1: =Pokemon!H1 | ... K1: =Pokemon!K1
A2: CHARACTERISTIC_HP-0 | B2: Loves to eat | C2: 食べるのが 大好き | D2: Adore manger | E2: Liebt es zu essen | F2: Le encanta comer | G2: Adora mangiare | H2: 먹는 것을 제일 좋아함 | I2: 非常喜歡吃東西 | J2: =IFERROR(__xludf.DUMMYFUNCTION("GOOGLETRANSLATE(I2,""zh_HANT"",""zh_HANS"")"),"非常喜欢吃东西") | K2: =F2
